Workbook

Sheet Dashboard
B1: 💰 Personal Finance Dashboard — 2026
B3: 💵 Net Salary | C3: 🔒 Fixed Costs | D3: 🎯 Spendable | E3: 💸 Spent (Month) | F3: 💰 Remaining | G3: 🏦 Saved
B4: =Setup!C2 -> 883 | C4: =Setup!C11 -> 135.1 | D4: =Setup!C14 -> 467.9 | E4: =SUMIF(Transactions!E:E,"<>Savings",Transactions!D:D) -> 204.82 | F4: =D4-E4 -> 263.08 | G4: =Setup!C16 -> 200
B6: 🏦 Emergency Fund Progress
B7: Current | C7: Target | D7: % Complete | E7: Months of Runway | F7: Status
B8: =Setup!C16 -> 200 | C8: =Setup!C17 -> 810.6 | D8: =IFERROR(Setup!C16/Setup!C17,0) -> 0.24673082 | E8: =IFERROR(Setup!C16/Setup!C11,0) -> 1.4803849 | F8: =IF(Setup!C16>=Setup!C17,"✅ Fully Funded",IF(Setup!C16/Setup!C17>=0.5,"🔄 Halfway there","🚀 Building up")) -> 🚀 Building up
B10: 📊 Category Spending vs Budget — May 2026 (update formula month as needed)
B11: Category | C11: Budget (OMR) | D11: Spent (OMR) | E11: Remaining (OMR) | F11: % Used | G11: Status | H11: W1 Spent | I11: W2 Spent | J11: W3 Spent | K11: W4 Spent
B12: Groceries | C12: =Budget_May!C7 -> 50 | D12: =Budget_May!H7 -> 0 | E12: =C12-D12 -> 50 | F12: =IFERROR(D12/C12,0) -> 0 | G12: =IF(C12=0,"—",IF(D12=0,"Not started",IF(D12>=C12,"❌ Over budget",IF(D12/C12>=0.8,"⚠️ Near limit","✅ On track")))) -> Not started | H12: =Budget_May!D7 -> 0 | I12: =Budget_May!E7 -> 0 | J12: =Budget_May!F7 -> 0 | K12: =Budget_May!G7 -> 0
B13: Dining Out | C13: =Budget_May!C8 -> 100 | D13: =Budget_May!H8 -> 13 | E13: =C13-D13 -> 87 | F13: =IFERROR(D13/C13,0) -> 0.13 | G13: =IF(C13=0,"—",IF(D13=0,"Not started",IF(D13>=C13,"❌ Over budget",IF(D13/C13>=0.8,"⚠️ Near limit","✅ On track")))) -> ✅ On track | H13: =Budget_May!D8 -> 0 | I13: =Budget_May!E8 -> 7.7 | J13: =Budget_May!F8 -> 5.3 | K13: =Budget_May!G8 -> 0
B14: Fuel | C14: =Budget_May!C9 -> 75 | D14: =Budget_May!H9 -> 15 | E14: =C14-D14 -> 60 | F14: =IFERROR(D14/C14,0) -> 0.2 | G14: =IF(C14=0,"—",IF(D14=0,"Not started",IF(D14>=C14,"❌ Over budget",IF(D14/C14>=0.8,"⚠️ Near limit","✅ On track")))) -> ✅ On track | H14: =Budget_May!D9 -> 0 | I14: =Budget_May!E9 -> 10 | J14: =Budget_May!F9 -> 5 | K14: =Budget_May!G9 -> 0
B15: Coffee | C15: =Budget_May!C10 -> 50 | D15: =Budget_May!H10 -> 5.8 | E15: =C15-D15 -> 44.2 | F15: =IFERROR(D15/C15,0) -> 0.116 | G15: =IF(C15=0,"—",IF(D15=0,"Not started",IF(D15>=C15,"❌ Over budget",IF(D15/C15>=0.8,"⚠️ Near limit","✅ On track")))) -> ✅ On track | H15: =Budget_May!D10 -> 0 | I15: =Budget_May!E10 -> 4.2 | J15: =Budget_May!F10 -> 1.6 | K15: =Budget_May!G10 -> 0
B16: Entertainment | C16: =Budget_May!C11 -> 20 | D16: =Budget_May!H11 -> 0 | E16: =C16-D16 -> 20 | F16: =IFERROR(D16/C16,0) -> 0 | G16: =IF(C16=0,"—",IF(D16=0,"Not started",IF(D16>=C16,"❌ Over budget",IF(D16/C16>=0.8,"⚠️ Near limit","✅ On track")))) -> Not started | H16: =Budget_May!D11 -> 0 | I16: =Budget_May!E11 -> 0 | J16: =Budget_May!F11 -> 0 | K16: =Budget_May!G11 -> 0
B17: Personal Care | C17: =Budget_May!C12 -> 15 | D17: =Budget_May!H12 -> 0 | E17: =C17-D17 -> 15 | F17: =IFERROR(D17/C17,0) -> 0 | G17: =IF(C17=0,"—",IF(D17=0,"Not started",IF(D17>=C17,"❌ Over budget",IF(D17/C17>=0.8,"⚠️ Near limit","✅ On track")))) -> Not started | H17: =Budget_May!D12 -> 0 | I17: =Budget_May!E12 -> 0 | J17: =Budget_May!F12 -> 0 | K17: =Budget_May!G12 -> 0
B18: Miscellaneous | C18: =Budget_May!C13 -> 40 | D18: =Budget_May!H13 -> 70 | E18: =C18-D18 -> -30 | F18: =IFERROR(D18/C18,0) -> 1.75 | G18: =IF(C18=0,"—",IF(D18=0,"Not started",IF(D18>=C18,"❌ Over budget",IF(D18/C18>=0.8,"⚠️ Near limit","✅ On track")))) -> ❌ Over budget | H18: =Budget_May!D13 -> 0 | I18: =Budget_May!E13 -> 0 | J18: =Budget_May!F13 -> 70 | K18: =Budget_May!G13 -> 0
B19: Subscriptions | C19: =Budget_May!C14 -> 10 | D19: =Budget_May!H14 -> 30 | E19: =C19-D19 -> -20 | F19: =IFERROR(D19/C19,0) -> 3 | G19: =IF(C19=0,"—",IF(D19=0,"Not started",IF(D19>=C19,"❌ Over budget",IF(D19/C19>=0.8,"⚠️ Near limit","✅ On track")))) -> ❌ Over budget | H19: =Budget_May!D14 -> 0 | I19: =Budget_May!E14 -> 30 | J19: =Budget_May!F14 -> 0 | K19: =Budget_May!G14 -> 0
B20: Savings | C20: =Budget_May!C15 -> 100 | D20: =Budget_May!H15 -> 0 | E20: =C20-D20 -> 100 | F20: =IFERROR(D20/C20,0) -> 0 | G20: =IF(C20=0,"—",IF(D20=0,"Not started",IF(D20>=C20,"❌ Over budget",IF(D20/C20>=0.8,"⚠️ Near limit","✅ On track")))) -> Not started | H20: =Budget_May!D15 -> 0 | I20: =Budget_May!E15 -> 0 | J20: =Budget_May!F15 -> 0 | K20: =Budget_May!G15 -> 0
B21: Other | C21: =Budget_May!C16 -> 0 | D21: =Budget_May!H16 -> 0 | E21: =C21-D21 -> 0 | F21: =IFERROR(D21/C21,0) -> 0 | G21: =IF(C21=0,"—",IF(D21=0,"Not started",IF(D21>=C21,"❌ Over budget",IF(D21/C21>=0.8,"⚠️ Near limit","✅ On track")))) -> — | H21: =Budget_May!D16 -> 0 | I21: =Budget_May!E16 -> 0 | J21: =Budget_May!F16 -> 0 | K21: =Budget_May!G16 -> 0
B22: TOTAL | C22: =SUM(C12:C21) -> 460 | D22: =SUM(D12:D21) -> 133.8 | E22: =SUM(E12:E21) -> 326.2 | F22: =IFERROR(D22/C22,0) -> 0.29086957 | H22: =SUM(H12:H21) -> 0 | I22: =SUM(I12:I21) -> 51.9 | J22: =SUM(J12:J21) -> 81.9 | K22: =SUM(K12:K21) -> 0
B24: 📅 Monthly Spending Summary — All 12 Months
B25: Month | C25: Total Budgeted | D25: Total Spent | E25: Remaining | F25: % Used | G25: Savings | H25: Top Category | I25: Notes
B26: January | C26: =SUM(Budget_Jan!C7:C16) -> 460 | D26: =SUM(Budget_Jan!H7:H16) -> 0 | E26: =C26-D26 -> 460 | F26: =IFERROR(D26/C26,0) -> 0 | G26: ='Savings & Goals'!C9 -> Amount Saved (OMR) | H26: {=IFERROR(INDEX(Budget_Jan!B7:B16,MATCH(MAX(Budget_Jan!H7:H16),Budget_Jan!H7:H16,0)),"—")} -> Groceries
B27: February | C27: =SUM(Budget_Feb!C7:C16) -> 460 | D27: =SUM(Budget_Feb!H7:H16) -> 0 | E27: =C27-D27 -> 460 | F27: =IFERROR(D27/C27,0) -> 0 | G27: ='Savings & Goals'!C10 -> 0 | H27: {=IFERROR(INDEX(Budget_Feb!B7:B16,MATCH(MAX(Budget_Feb!H7:H16),Budget_Feb!H7:H16,0)),"—")} -> Groceries | I27: Jamʿiyya starts
B28: March | C28: =SUM(Budget_Mar!C7:C16) -> 460 | D28: =SUM(Budget_Mar!H7:H16) -> 0 | E28: =C28-D28 -> 460 | F28: =IFERROR(D28/C28,0) -> 0 | G28: ='Savings & Goals'!C11 -> 0 | H28: {=IFERROR(INDEX(Budget_Mar!B7:B16,MATCH(MAX(Budget_Mar!H7:H16),Budget_Mar!H7:H16,0)),"—")} -> Groceries
B29: April | C29: =SUM(Budget_Apr!C7:C16) -> 460 | D29: =SUM(Budget_Apr!H7:H16) -> 0 | E29: =C29-D29 -> 460 | F29: =IFERROR(D29/C29,0) -> 0 | G29: ='Savings & Goals'!C12 -> 0 | H29: {=IFERROR(INDEX(Budget_Apr!B7:B16,MATCH(MAX(Budget_Apr!H7:H16),Budget_Apr!H7:H16,0)),"—")} -> Groceries | I29: Last Jamʿiyya month
B30: May | C30: =SUM(Budget_May!C7:C16) -> 460 | D30: =SUM(Budget_May!H7:H16) -> 133.8 | E30: =C30-D30 -> 326.2 | F30: =IFERROR(D30/C30,0) -> 0.29086957 | G30: ='Savings & Goals'!C13 -> 0 | H30: {=IFERROR(INDEX(Budget_May!B7:B16,MATCH(MAX(Budget_May!H7:H16),Budget_May!H7:H16,0)),"—")} -> Miscellaneous
B31: June | C31: =SUM(Budget_Jun!C7:C16) -> 460 | D31: =SUM(Budget_Jun!H7:H16) -> 155.02 | E31: =C31-D31 -> 304.98 | F31: =IFERROR(D31/C31,0) -> 0.337 | G31: ='Savings & Goals'!C14 -> 0 | H31: {=IFERROR(INDEX(Budget_Jun!B7:B16,MATCH(MAX(Budget_Jun!H7:H16),Budget_Jun!H7:H16,0)),"—")} -> Savings
B32: July | C32: =SUM(Budget_Jul!C7:C16) -> 460 | D32: =SUM(Budget_Jul!H7:H16) -> 0 | E32: =C32-D32 -> 460 | F32: =IFERROR(D32/C32,0) -> 0 | G32: ='Savings & Goals'!C15 -> 0 | H32: {=IFERROR(INDEX(Budget_Jul!B7:B16,MATCH(MAX(Budget_Jul!H7:H16),Budget_Jul!H7:H16,0)),"—")} -> Groceries | I32: ⭐ 1,400 OMR payout!
B33: August | C33: =SUM(Budget_Aug!C7:C16) -> 460 | D33: =SUM(Budget_Aug!H7:H16) -> 0 | E33: =C33-D33 -> 460 | F33: =IFERROR(D33/C33,0) -> 0 | G33: ='Savings & Goals'!C16 -> 0 | H33: {=IFERROR(INDEX(Budget_Aug!B7:B16,MATCH(MAX(Budget_Aug!H7:H16),Budget_Aug!H7:H16,0)),"—")} -> Groceries
B34: September | C34: =SUM(Budget_Sep!C7:C16) -> 460 | D34: =SUM(Budget_Sep!H7:H16) -> 0 | E34: =C34-D34 -> 460 | F34: =IFERROR(D34/C34,0) -> 0 | G34: ='Savings & Goals'!C17 -> 0 | H34: {=IFERROR(INDEX(Budget_Sep!B7:B16,MATCH(MAX(Budget_Sep!H7:H16),Budget_Sep!H7:H16,0)),"—")} -> Groceries
B35: October | C35: =SUM(Budget_Oct!C7:C16) -> 460 | D35: =SUM(Budget_Oct!H7:H16) -> 0 | E35: =C35-D35 -> 460 | F35: =IFERROR(D35/C35,0) -> 0 | G35: ='Savings & Goals'!C18 -> 0 | H35: {=IFERROR(INDEX(Budget_Oct!B7:B16,MATCH(MAX(Budget_Oct!H7:H16),Budget_Oct!H7:H16,0)),"—")} -> Groceries
B36: November | C36: =SUM(Budget_Nov!C7:C16) -> 460 | D36: =SUM(Budget_Nov!H7:H16) -> 0 | E36: =C36-D36 -> 460 | F36: =IFERROR(D36/C36,0) -> 0 | G36: ='Savings & Goals'!C19 -> 0 | H36: {=IFERROR(INDEX(Budget_Nov!B7:B16,MATCH(MAX(Budget_Nov!H7:H16),Budget_Nov!H7:H16,0)),"—")} -> Groceries
B37: December | C37: =SUM(Budget_Dec!C7:C16) -> 460 | D37: =SUM(Budget_Dec!H7:H16) -> 0 | E37: =C37-D37 -> 460 | F37: =IFERROR(D37/C37,0) -> 0 | G37: ='Savings & Goals'!C20 -> 0 | H37: {=IFERROR(INDEX(Budget_Dec!B7:B16,MATCH(MAX(Budget_Dec!H7:H16),Budget_Dec!H7:H16,0)),"—")} -> Groceries | I37: Year end review
B39: 💳 Fixed Monthly Outflows | F39: 🎯 Savings Goals Snapshot
B40: Item | C40: Amount (OMR) | D40: % of Salary | E40: Notes | F40: Goal | G40: Current | H40: Target | I40: Progress
B41: Loan Repayment | C41: =Setup!C5 -> 603 | D41: =IFERROR(C41/Setup!C2,0) -> 0.68289921 | E41: Deducted from salary | F41: Emergency Fund | G41: ='Savings & Goals'!D3 -> 250 | H41: ='Savings & Goals'!E3 -> 2490 | I41: =IFERROR(G41/H41,0) -> 0.10040161
B42: Jamʿiyya | C42: =Setup!C9 -> 100 | D42: =IFERROR(C42/Setup!C2,0) -> 0.11325028 | E42: Ends Apr 2027 | Payout Jul 2026 | F42: Jamʿiyya Buffer | G42: ='Savings & Goals'!D4 -> 0 | H42: ='Savings & Goals'!E4 -> 1400 | I42: =IFERROR(G42/H42,0) -> 0
B43: Phone Installment | C43: =Setup!C8 -> 24.1 | D43: =IFERROR(C43/Setup!C2,0) -> 0.027293318 | E43: 24 months from Mar 2026 | F43: General Savings | G43: ='Savings & Goals'!D5 -> 0 | H43: ='Savings & Goals'!E5 -> 1200 | I43: =IFERROR(G43/H43,0) -> 0
B44: Internet | C44: =Setup!C10 -> 11 | D44: =IFERROR(C44/Setup!C2,0) -> 0.012457531 | E44: Monthly
B45: TOTAL FIXED | C45: =Setup!C11 -> 135.1 | D45: =IFERROR(Setup!C11/Setup!C2,0) -> 0.15300113

Sheet Setup
B1: ⚙️ Profile & Setup
B2: Net Monthly Salary (OMR) | C2: 883
B3: Irregular / Extra Income (OMR) | C3: 70
B4: Salary Pay Date | C4: 23rd
B5: Net after loan deduction | C5: =C2-280 -> 603
B7: ── Fixed Outflows ──
B8: Phone Installment | C8: 24.1
B9: Jamʿiyya (ends Apr 2027) | C9: 100
B10: Internet | C10: 11
B11: Total Fixed | C11: =SUM(C8:C10) -> 135.1
B13: Savings Goal / month | C13: 0
B14: Spendable (after fixed+savings) | C14: =C5-C11-C13 -> 467.9
B16: Current Savings / Emergency Fund | C16: 200
B17: Emergency Fund Target (6×fixed) | C17: =C11*6 -> 810.6
B18: Months of Runway | C18: =IFERROR(C16/C11,0) -> 1.4803849

Sheet Transactions
B1: 📝 Transaction Log
B2: Date | C2: Description | D2: Amount (OMR) | E2: Category | F2: Merchant / Note | G2: Month (auto)
B3: 46143 | C3: Opening balance | D3: 0 | E3: Savings | F3: Starting balance | G3: =IF(B3="","",TEXT(B3,"MMMM YYYY")) -> May 2026
B4: 46159 | C4: برجيل | D4: 70 | E4: Miscellaneous | F4: Starting balance | G4: =IF(B4="","",TEXT(B4,"MMMM YYYY")) -> May 2026
B5: 46159 | C5: عشا | D5: 1.9 | E5: Dining Out | F5: Starting balance | G5: =IF(B5="","",TEXT(B5,"MMMM YYYY")) -> May 2026
B6: 46159 | D6: 5 | E6: Fuel | F6: Starting balance | G6: =IF(B6="","",TEXT(B6,"MMMM YYYY")) -> May 2026
B7: 46159 | D7: 1.6 | E7: Coffee | F7: Starting balance | G7: =IF(B7="","",TEXT(B7,"MMMM YYYY")) -> May 2026
B8: 46158 | D8: 3.4 | E8: Dining Out | F8: Starting balance | G8: =IF(B8="","",TEXT(B8,"MMMM YYYY")) -> May 2026
B9: 46157 | C9: swimming coach | D9: 30 | E9: Subscriptions | F9: Starting balance | G9: =IF(B9="","",TEXT(B9,"MMMM YYYY")) -> May 2026
B10: 46157 | C10: acai | D10: 4.2 | E10: Coffee | F10: Starting balance | G10: =IF(B10="","",TEXT(B10,"MMMM YYYY")) -> May 2026
B11: 46157 | D11: 10 | E11: Fuel | F11: Starting balance | G11: =IF(B11="","",TEXT(B11,"MMMM YYYY")) -> May 2026
B12: 46156 | D12: 7.7 | E12: Dining Out | F12: Starting balance | G12: =IF(B12="","",TEXT(B12,"MMMM YYYY")) -> May 2026
B13: 46158 | G13: =IF(B13="","",TEXT(B13,"MMMM YYYY")) -> May 2026
B14: 46174 | D14: 3 | E14: Fuel | G14: =IF(B14="","",TEXT(B14,"MMMM YYYY")) -> June 2026
B15: 46174 | D15: 3.35 | E15: Dining Out | G15: =IF(B15="","",TEXT(B15,"MMMM YYYY")) -> June 2026
B16: 46174 | C16: ترتان | D16: 1.5 | E16: Entertainment | G16: =IF(B16="","",TEXT(B16,"MMMM YYYY")) -> June 2026
B17: 46174 | D17: 3.87 | E17: Groceries | G17: =IF(B17="","",TEXT(B17,"MMMM YYYY")) -> June 2026
B18: 46174 | D18: 1 | E18: Groceries | G18: =IF(B18="","",TEXT(B18,"MMMM YYYY")) -> June 2026
B19: 46174 | D19: 2.3 | E19: Dining Out | G19: =IF(B19="","",TEXT(B19,"MMMM YYYY")) -> June 2026
B20: 46174 | D20: 5.6 | E20: Dining Out | G20: =IF(B20="","",TEXT(B20,"MMMM YYYY")) -> June 2026
B21: 46174 | C21: aljabal trip | D21: 32 | E21: Savings | G21: =IF(B21="","",TEXT(B21,"MMMM YYYY")) -> June 2026
B22: 46174 | D22: 2.1 | E22: Coffee | G22: =IF(B22="","",TEXT(B22,"MMMM YYYY")) -> June 2026
B23: 46174 | C23: gift asaad | D23: 52 | E23: Savings | G23: =IF(B23="","",TEXT(B23,"MMMM YYYY")) -> June 2026
B24: 46174 | D24: 1 | E24: Personal Care | G24: =IF(B24="","",TEXT(B24,"MMMM YYYY")) -> June 2026
B25: 46174 | D25: 16.5 | E25: Other | G25: =IF(B25="","",TEXT(B25,"MMMM YYYY")) -> June 2026
B26: 46174 | D26: 6 | E26: Other | G26: =IF(B26="","",TEXT(B26,"MMMM YYYY")) -> June 2026
B27: 46174 | D27: 5.4 | E27: Coffee | G27: =IF(B27="","",TEXT(B27,"MMMM YYYY")) -> June 2026
B28: 46174 | C28: eid day | D28: 5.6 | E28: Coffee | G28: =IF(B28="","",TEXT(B28,"MMMM YYYY")) -> June 2026
B29: 46174 | C29: B+F | D29: 9 | E29: Dining Out | G29: =IF(B29="","",TEXT(B29,"MMMM YYYY")) -> June 2026
B30: 46181 | D30: 1.9 | E30: Coffee | G30: =IF(B30="","",TEXT(B30,"MMMM YYYY")) -> June 2026
B31: 46181 | D31: 2.9 | E31: Groceries | G31: =IF(B31="","",TEXT(B31,"MMMM YYYY")) -> June 2026
B32: 46174 | G32: =IF(B32="","",TEXT(B32,"MMMM YYYY")) -> June 2026
B33: 46174 | G33: =IF(B33="","",TEXT(B33,"MMMM YYYY")) -> June 2026
B34: 46174
B35: 46174
B36: 46174

Sheet Savings & Goals
B1: 🎯 Savings & Goals Tracker
B2: Goal | C2: Target Date | D2: Current (OMR) | E2: Target (OMR) | F2: Progress | G2: Status
B3: Emergency Fund | C3: 2026-12-31 | D3: 250 | E3: 2490 | F3: =IFERROR(D3/E3,0) -> 0.10040161 | G3: =IF(D3>=E3,"✅ Complete",IF(D3/E3>=0.5,"🔄 Halfway","🚀 In Progress")) -> 🚀 In Progress
B4: Jamʿiyya Payout Buffer | C4: 2026-07-01 | D4: 0 | E4: 1400 | F4: =IFERROR(D4/E4,0) -> 0 | G4: =IF(D4>=E4,"✅ Complete",IF(D4/E4>=0.5,"🔄 Halfway","🚀 In Progress")) -> 🚀 In Progress
B5: General Savings | C5: 2027-01-01 | D5: 0 | E5: 1200 | F5: =IFERROR(D5/E5,0) -> 0 | G5: =IF(D5>=E5,"✅ Complete",IF(D5/E5>=0.5,"🔄 Halfway","🚀 In Progress")) -> 🚀 In Progress
B6: ✈️ Bali Trip | C6: 2026-09-01 | D6: 0 | E6: 900 | F6: =IFERROR(D6/E6,0) -> 0 | G6: =IF(D6>=E6,"✅ Funded!",IF(D6/E6>=0.5,"🔄 Halfway","🚀 Saving...")) -> 🚀 Saving...
B8: 📅 Monthly Savings Log
B9: Month | C9: Amount Saved (OMR) | D9: Running Total | E9: Notes
B10: January 2026 | C10: 0 | D10: =C10 -> 0
B11: February 2026 | C11: 0 | D11: =D10+C11 -> 0
B12: March 2026 | C12: 0 | D12: =D11+C12 -> 0
B13: April 2026 | C13: 0 | D13: =D12+C13 -> 0
B14: May 2026 | C14: 0 | D14: =D13+C14 -> 0
B15: June 2026 | C15: 0 | D15: =D14+C15 -> 0
B16: July 2026 | C16: 0 | D16: =D15+C16 -> 0
B17: August 2026 | C17: 0 | D17: =D16+C17 -> 0
B18: September 2026 | C18: 0 | D18: =D17+C18 -> 0
B19: October 2026 | C19: 0 | D19: =D18+C19 -> 0
B20: November 2026 | C20: 0 | D20: =D19+C20 -> 0
B21: December 2026 | C21: 0 | D21: =D20+C21 -> 0
B24: 🌴 Bali Trip Planner — September 2026
B26: Expense Item | C26: Estimated (OMR) | D26: Actual (OMR) | E26: Difference | F26: Status | G26: Notes
B27: ✈️ Flights (Return) | C27: 280 | D27: 212 | E27: =C27-D27 -> 68 | F27: =IF(D27=0,"Not paid",IF(D27<=C27,"✅ OK","⚠️ Over")) -> ✅ OK | G27: Muscat ↔ Bali — check Oman Air / AirAsia
B28: 🏨 Accommodation (7 nights) | C28: 200 | D28: 0 | E28: =C28-D28 -> 200 | F28: =IF(D28=0,"Not paid",IF(D28<=C28,"✅ OK","⚠️ Over")) -> Not paid | G28: ~28 OMR/night — mid-range villa
B29: 🍜 Food & Dining | C29: 120 | D29: 0 | E29: =C29-D29 -> 120 | F29: =IF(D29=0,"Not paid",IF(D29<=C29,"✅ OK","⚠️ Over")) -> Not paid | G29: ~17 OMR/day — mix local & restaurants
B30: 🛵 Transport (scooter/taxi) | C30: 30 | D30: 0 | E30: =C30-D30 -> 30 | F30: =IF(D30=0,"Not paid",IF(D30<=C30,"✅ OK","⚠️ Over")) -> Not paid | G30: Scooter rental + grab taxi
B31: 🏄 Activities & Tours | C31: 120 | D31: 0 | E31: =C31-D31 -> 120 | F31: =IF(D31=0,"Not paid",IF(D31<=C31,"✅ OK","⚠️ Over")) -> Not paid | G31: Surfing, temples, rice terraces
B32: 🛍️ Shopping & Souvenirs | C32: 80 | D32: 0 | E32: =C32-D32 -> 80 | F32: =IF(D32=0,"Not paid",IF(D32<=C32,"✅ OK","⚠️ Over")) -> Not paid | G32: Clothing, gifts, crafts
B33: 🔒 Travel Insurance | C33: 0 | D33: 0 | E33: =C33-D33 -> 0 | F33: =IF(D33=0,"Not paid",IF(D33<=C33,"✅ OK","⚠️ Over")) -> Not paid | G33: Highly recommended
B34: 💊 Misc / Emergency buffer | C34: 20 | D34: 0 | E34: =C34-D34 -> 20 | F34: =IF(D34=0,"Not paid",IF(D34<=C34,"✅ OK","⚠️ Over")) -> Not paid | G34: Pharmacy, sim card, tips
B35: TOTAL | C35: =SUM(C27:C34) -> 850 | D35: =SUM(D27:D34) -> 212 | E35: =C35-D35 -> 638
B38: 💰 Bali Savings Plan — How to reach 900 OMR by September
B40: Source | C40: Amount (OMR) | D40: When | E40: Running Total | F40: Notes
B41: Current savings | C41: 250 | D41: Now | E41: =C41 -> 250 | F41: Starting point
B42: Jun 2026 — monthly saving | C42: 100 | D42: 23 Jun | E42: =E41+C42 -> 350 | F42: Regular 100 OMR/month goal
B43: Jul 2026 — monthly saving | C43: 100 | D43: 23 Jul | E43: =E42+C43 -> 450 | F43: Regular 100 OMR/month goal
B44: Jul 2026 — Jamʿiyya payout | C44: 900 | D44: Jul 2026 | E44: =E43+C44 -> 1350 | F44: 1,400 OMR in — allocate 900 to Bali fund
B45: Aug 2026 — monthly saving | C45: 100 | D45: 23 Aug | E45: =E44+C45 -> 1450 | F45: Regular 100 OMR/month goal
B47: 🌴 Bali Budget | C47: 900 OMR
B48: ✅ Funded by July payout alone | C48: Yes
...

Sheet Annual Forecast
B1: 📈 Annual Forecast 2026
B2: Item | C2: Jan | D2: Feb | E2: Mar | F2: Apr | G2: May | H2: Jun | I2: Jul | J2: Aug | K2: Sep | L2: Oct | M2: Nov | N2: Dec
B3: Net Income | C3: =Setup!C2 -> 883 | D3: =Setup!C2 -> 883 | E3: =Setup!C2 -> 883 | F3: =Setup!C2 -> 883 | G3: =Setup!C2 -> 883 | H3: =Setup!C2 -> 883 | I3: =Setup!C2 -> 883 | J3: =Setup!C2 -> 883 | K3: =Setup!C2 -> 883 | L3: =Setup!C2 -> 883 | M3: =Setup!C2 -> 883 | N3: =Setup!C2 -> 883
B4: Loan Repayment | C4: 280 | D4: 280 | E4: 280 | F4: 280 | G4: 280 | H4: 280 | I4: 280 | J4: 280 | K4: 280 | L4: 280 | M4: 280 | N4: 280
B5: Jamʿiyya | C5: 100 | D5: 100 | E5: 100 | F5: 100 | G5: 100 | H5: 100 | I5: 100 | J5: 100 | K5: 100 | L5: 100 | M5: 100 | N5: 100
B6: Phone | C6: 24 | D6: 24 | E6: 24 | F6: 24 | G6: 24 | H6: 24 | I6: 24 | J6: 24 | K6: 24 | L6: 24 | M6: 24 | N6: 24
B7: Internet | C7: 11 | D7: 11 | E7: 11 | F7: 11 | G7: 11 | H7: 11 | I7: 11 | J7: 11 | K7: 11 | L7: 11 | M7: 11 | N7: 11
B8: Total Fixed | C8: =C4+C5+C6+C7 -> 415 | D8: =D4+D5+D6+D7 -> 415 | E8: =E4+E5+E6+E7 -> 415 | F8: =F4+F5+F6+F7 -> 415 | G8: =G4+G5+G6+G7 -> 415 | H8: =H4+H5+H6+H7 -> 415 | I8: =I4+I5+I6+I7 -> 415 | J8: =J4+J5+J6+J7 -> 415 | ... N8: =N4+N5+N6+N7 -> 415
B9: Spendable | C9: =C3-C8 -> 468 | D9: =D3-D8 -> 468 | E9: =E3-E8 -> 468 | F9: =F3-F8 -> 468 | G9: =G3-G8 -> 468 | H9: =H3-H8 -> 468 | I9: =I3-I8 -> 468 | J9: =J3-J8 -> 468 | ... N9: =N3-N8 -> 468
B10: Savings Goal | C10: 100 | D10: 100 | E10: 100 | F10: 100 | G10: 100 | H10: 100 | I10: 100 | J10: 100 | K10: 100 | L10: 100 | M10: 100 | N10: 100
B13: ⭐ July 2026: Jamʿiyya payout of 1,400 OMR — allocated to Emergency Fund by default
B17: 📊 Monthly Budget Summary (Budgeted vs Spent)
B18: Category | C18: Jan | D18: Feb | E18: Mar | F18: Apr | G18: May | H18: Jun | I18: Jul | J18: Aug | K18: Sep | L18: Oct | M18: Nov | N18: Dec
B19: Groceries | C19: =IFERROR(Budget_Jan!H7,0) -> 0 | D19: =IFERROR(Budget_Feb!H7,0) -> 0 | E19: =IFERROR(Budget_Mar!H7,0) -> 0 | F19: =IFERROR(Budget_Apr!H7,0) -> 0 | G19: =IFERROR(Budget_May!H7,0) -> 0 | H19: =IFERROR(Budget_Jun!H7,0) -> 7.77 | I19: =IFERROR(Budget_Jul!H7,0) -> 0 | J19: =IFERROR(Budget_Aug!H7,0) -> 0 | K19: =IFERROR(Budget_Sep!H7,0) -> 0 | L19: =IFERROR(Budget_Oct!H7,0) -> 0 | M19: =IFERROR(Budget_Nov!H7,0) -> 0 | N19: =IFERROR(Budget_Dec!H7,0) -> 0
B20: Dining Out | C20: =IFERROR(Budget_Jan!H8,0) -> 0 | D20: =IFERROR(Budget_Feb!H8,0) -> 0 | E20: =IFERROR(Budget_Mar!H8,0) -> 0 | F20: =IFERROR(Budget_Apr!H8,0) -> 0 | G20: =IFERROR(Budget_May!H8,0) -> 13 | H20: =IFERROR(Budget_Jun!H8,0) -> 20.25 | I20: =IFERROR(Budget_Jul!H8,0) -> 0 | J20: =IFERROR(Budget_Aug!H8,0) -> 0 | K20: =IFERROR(Budget_Sep!H8,0) -> 0 | L20: =IFERROR(Budget_Oct!H8,0) -> 0 | M20: =IFERROR(Budget_Nov!H8,0) -> 0 | N20: =IFERROR(Budget_Dec!H8,0) -> 0
B21: Fuel | C21: =IFERROR(Budget_Jan!H9,0) -> 0 | D21: =IFERROR(Budget_Feb!H9,0) -> 0 | E21: =IFERROR(Budget_Mar!H9,0) -> 0 | F21: =IFERROR(Budget_Apr!H9,0) -> 0 | G21: =IFERROR(Budget_May!H9,0) -> 15 | H21: =IFERROR(Budget_Jun!H9,0) -> 3 | I21: =IFERROR(Budget_Jul!H9,0) -> 0 | J21: =IFERROR(Budget_Aug!H9,0) -> 0 | K21: =IFERROR(Budget_Sep!H9,0) -> 0 | L21: =IFERROR(Budget_Oct!H9,0) -> 0 | M21: =IFERROR(Budget_Nov!H9,0) -> 0 | N21: =IFERROR(Budget_Dec!H9,0) -> 0
B22: Coffee | C22: =IFERROR(Budget_Jan!H10,0) -> 0 | D22: =IFERROR(Budget_Feb!H10,0) -> 0 | E22: =IFERROR(Budget_Mar!H10,0) -> 0 | F22: =IFERROR(Budget_Apr!H10,0) -> 0 | G22: =IFERROR(Budget_May!H10,0) -> 5.8 | H22: =IFERROR(Budget_Jun!H10,0) -> 15 | I22: =IFERROR(Budget_Jul!H10,0) -> 0 | J22: =IFERROR(Budget_Aug!H10,0) -> 0 | K22: =IFERROR(Budget_Sep!H10,0) -> 0 | L22: =IFERROR(Budget_Oct!H10,0) -> 0 | M22: =IFERROR(Budget_Nov!H10,0) -> 0 | N22: =IFERROR(Budget_Dec!H10,0) -> 0
B23: Entertainment | C23: =IFERROR(Budget_Jan!H11,0) -> 0 | D23: =IFERROR(Budget_Feb!H11,0) -> 0 | E23: =IFERROR(Budget_Mar!H11,0) -> 0 | F23: =IFERROR(Budget_Apr!H11,0) -> 0 | G23: =IFERROR(Budget_May!H11,0) -> 0 | H23: =IFERROR(Budget_Jun!H11,0) -> 1.5 | I23: =IFERROR(Budget_Jul!H11,0) -> 0 | J23: =IFERROR(Budget_Aug!H11,0) -> 0 | K23: =IFERROR(Budget_Sep!H11,0) -> 0 | L23: =IFERROR(Budget_Oct!H11,0) -> 0 | M23: =IFERROR(Budget_Nov!H11,0) -> 0 | N23: =IFERROR(Budget_Dec!H11,0) -> 0
B24: Personal Care | C24: =IFERROR(Budget_Jan!H12,0) -> 0 | D24: =IFERROR(Budget_Feb!H12,0) -> 0 | E24: =IFERROR(Budget_Mar!H12,0) -> 0 | F24: =IFERROR(Budget_Apr!H12,0) -> 0 | G24: =IFERROR(Budget_May!H12,0) -> 0 | H24: =IFERROR(Budget_Jun!H12,0) -> 1 | I24: =IFERROR(Budget_Jul!H12,0) -> 0 | J24: =IFERROR(Budget_Aug!H12,0) -> 0 | K24: =IFERROR(Budget_Sep!H12,0) -> 0 | L24: =IFERROR(Budget_Oct!H12,0) -> 0 | M24: =IFERROR(Budget_Nov!H12,0) -> 0 | N24: =IFERROR(Budget_Dec!H12,0) -> 0
B25: Miscellaneous | C25: =IFERROR(Budget_Jan!H13,0) -> 0 | D25: =IFERROR(Budget_Feb!H13,0) -> 0 | E25: =IFERROR(Budget_Mar!H13,0) -> 0 | F25: =IFERROR(Budget_Apr!H13,0) -> 0 | G25: =IFERROR(Budget_May!H13,0) -> 70 | H25: =IFERROR(Budget_Jun!H13,0) -> 0 | I25: =IFERROR(Budget_Jul!H13,0) -> 0 | J25: =IFERROR(Budget_Aug!H13,0) -> 0 | K25: =IFERROR(Budget_Sep!H13,0) -> 0 | L25: =IFERROR(Budget_Oct!H13,0) -> 0 | M25: =IFERROR(Budget_Nov!H13,0) -> 0 | N25: =IFERROR(Budget_Dec!H13,0) -> 0
B26: Subscriptions | C26: =IFERROR(Budget_Jan!H14,0) -> 0 | D26: =IFERROR(Budget_Feb!H14,0) -> 0 | E26: =IFERROR(Budget_Mar!H14,0) -> 0 | F26: =IFERROR(Budget_Apr!H14,0) -> 0 | G26: =IFERROR(Budget_May!H14,0) -> 30 | H26: =IFERROR(Budget_Jun!H14,0) -> 0 | I26: =IFERROR(Budget_Jul!H14,0) -> 0 | J26: =IFERROR(Budget_Aug!H14,0) -> 0 | K26: =IFERROR(Budget_Sep!H14,0) -> 0 | L26: =IFERROR(Budget_Oct!H14,0) -> 0 | M26: =IFERROR(Budget_Nov!H14,0) -> 0 | N26: =IFERROR(Budget_Dec!H14,0) -> 0
B27: Savings | C27: =IFERROR(Budget_Jan!H15,0) -> 0 | D27: =IFERROR(Budget_Feb!H15,0) -> 0 | E27: =IFERROR(Budget_Mar!H15,0) -> 0 | F27: =IFERROR(Budget_Apr!H15,0) -> 0 | G27: =IFERROR(Budget_May!H15,0) -> 0 | H27: =IFERROR(Budget_Jun!H15,0) -> 84 | I27: =IFERROR(Budget_Jul!H15,0) -> 0 | J27: =IFERROR(Budget_Aug!H15,0) -> 0 | K27: =IFERROR(Budget_Sep!H15,0) -> 0 | L27: =IFERROR(Budget_Oct!H15,0) -> 0 | M27: =IFERROR(Budget_Nov!H15,0) -> 0 | N27: =IFERROR(Budget_Dec!H15,0) -> 0
B28: Other | C28: =IFERROR(Budget_Jan!H16,0) -> 0 | D28: =IFERROR(Budget_Feb!H16,0) -> 0 | E28: =IFERROR(Budget_Mar!H16,0) -> 0 | F28: =IFERROR(Budget_Apr!H16,0) -> 0 | G28: =IFERROR(Budget_May!H16,0) -> 0 | H28: =IFERROR(Budget_Jun!H16,0) -> 22.5 | I28: =IFERROR(Budget_Jul!H16,0) -> 0 | J28: =IFERROR(Budget_Aug!H16,0) -> 0 | K28: =IFERROR(Budget_Sep!H16,0) -> 0 | L28: =IFERROR(Budget_Oct!H16,0) -> 0 | M28: =IFERROR(Budget_Nov!H16,0) -> 0 | N28: =IFERROR(Budget_Dec!H16,0) -> 0

Sheet Budget_Jan
B1: 💰 Weekly Spending Tracker — January 2026
B3: Net Salary | C3: Fixed Outflows | D3: Savings Goal | E3: Spendable
B4: =Setup!C2 -> 883 | C4: =Setup!C11 -> 135.1 | D4: =Setup!C13 -> 0 | E4: =Setup!C14 -> 467.9
B6: Category | C6: Monthly Budget | D6: Week 1 Jan 1–Jan 7 | E6: Week 2 Jan 8–Jan 15 | F6: Week 3 Jan 16–Jan 22 | G6: Week 4 Jan 23–Jan 31 | H6: Total Spent | I6: Remaining | J6: % Used | K6: Status
B7: Groceries | C7: 50 | D7: =IFERROR(SUMPRODUCT((Transactions!E$3:E$2000="Groceries")*ISNUMBER(Transactions!B$3:B$2000)*(Transactions!B$3:B$2000>=DATE(2026,1,1))*(Transactions!B$3:B$2000<=DATE(2026,1,7))*(Transactions!D$3:D$2000)),0) -> 0 | E7: =IFERROR(SUMPRODUCT((Transactions!E$3:E$2000="Groceries")*ISNUMBER(Transactions!B$3:B$2000)*(Transactions!B$3:B$2000>=DATE(2026,1,8))*(Transactions!B$3:B$2000<=DATE(2026,1,15))*(Transactions!D$3:D$2000)),0) -> 0 | F7: =IFERROR(SUMPRODUCT((Transactions!E$3:E$2000="Groceries")*ISNUMBER(Transactions!B$3:B$2000)*(Transactions!B$3:B$2000>=DATE(2026,1,16))*(Transactions!B$3:B$2000<=DATE(2026,1,22))*(Transactions!D$3:D$2000)),0) -> 0 | G7: =IFERROR(SUMPRODUCT((Transactions!E$3:E$2000="Groceries")*ISNUMBER(Transactions!B$3:B$2000)*(Transactions!B$3:B$2000>=DATE(2026,1,23))*(Transactions!B$3:B$2000<=DATE(2026,1,31))*(Transactions!D$3:D$2000)),0) -> 0 | H7: =SUM(D7:G7) -> 0 | I7: =C7-H7 -> 50 | J7: =IFERROR(H7/C7,0) -> 0 | K7: =IF(C7=0,"—",IF(H7=0,"Not started",IF(H7>=C7,"❌ Over budget",IF(H7/C7>=0.8,"⚠️ Near limit","✅ On track")))) -> Not started
B8: Dining Out | C8: 100 | D8: =IFERROR(SUMPRODUCT((Transactions!E$3:E$2000="Dining Out")*ISNUMBER(Transactions!B$3:B$2000)*(Transactions!B$3:B$2000>=DATE(2026,1,1))*(Transactions!B$3:B$2000<=DATE(2026,1,7))*(Transactions!D$3:D$2000)),0) -> 0 | E8: =IFERROR(SUMPRODUCT((Transactions!E$3:E$2000="Dining Out")*ISNUMBER(Transactions!B$3:B$2000)*(Transactions!B$3:B$2000>=DATE(2026,1,8))*(Transactions!B$3:B$2000<=DATE(2026,1,15))*(Transactions!D$3:D$2000)),0) -> 0 | F8: =IFERROR(SUMPRODUCT((Transactions!E$3:E$2000="Dining Out")*ISNUMBER(Transactions!B$3:B$2000)*(Transactions!B$3:B$2000>=DATE(2026,1,16))*(Transactions!B$3:B$2000<=DATE(2026,1,22))*(Transactions!D$3:D$2000)),0) -> 0 | G8: =IFERROR(SUMPRODUCT((Transactions!E$3:E$2000="Dining Out")*ISNUMBER(Transactions!B$3:B$2000)*(Transactions!B$3:B$2000>=DATE(2026,1,23))*(Transactions!B$3:B$2000<=DATE(2026,1,31))*(Transactions!D$3:D$2000)),0) -> 0 | H8: =SUM(D8:G8) -> 0 | I8: =C8-H8 -> 100 | J8: =IFERROR(H8/C8,0) -> 0 | K8: =IF(C8=0,"—",IF(H8=0,"Not started",IF(H8>=C8,"❌ Over budget",IF(H8/C8>=0.8,"⚠️ Near limit","✅ On track")))) -> Not started
B9: Fuel | C9: 75 | D9: =IFERROR(SUMPRODUCT((Transactions!E$3:E$2000="Fuel")*ISNUMBER(Transactions!B$3:B$2000)*(Transactions!B$3:B$2000>=DATE(2026,1,1))*(Transactions!B$3:B$2000<=DATE(2026,1,7))*(Transactions!D$3:D$2000)),0) -> 0 | E9: =IFERROR(SUMPRODUCT((Transactions!E$3:E$2000="Fuel")*ISNUMBER(Transactions!B$3:B$2000)*(Transactions!B$3:B$2000>=DATE(2026,1,8))*(Transactions!B$3:B$2000<=DATE(2026,1,15))*(Transactions!D$3:D$2000)),0) -> 0 | F9: =IFERROR(SUMPRODUCT((Transactions!E$3:E$2000="Fuel")*ISNUMBER(Transactions!B$3:B$2000)*(Transactions!B$3:B$2000>=DATE(2026,1,16))*(Transactions!B$3:B$2000<=DATE(2026,1,22))*(Transactions!D$3:D$2000)),0) -> 0 | G9: =IFERROR(SUMPRODUCT((Transactions!E$3:E$2000="Fuel")*ISNUMBER(Transactions!B$3:B$2000)*(Transactions!B$3:B$2000>=DATE(2026,1,23))*(Transactions!B$3:B$2000<=DATE(2026,1,31))*(Transactions!D$3:D$2000)),0) -> 0 | H9: =SUM(D9:G9) -> 0 | I9: =C9-H9 -> 75 | J9: =IFERROR(H9/C9,0) -> 0 | K9: =IF(C9=0,"—",IF(H9=0,"Not started",IF(H9>=C9,"❌ Over budget",IF(H9/C9>=0.8,"⚠️ Near limit","✅ On track")))) -> Not started
B10: Coffee | C10: 50 | D10: =IFERROR(SUMPRODUCT((Transactions!E$3:E$2000="Coffee")*ISNUMBER(Transactions!B$3:B$2000)*(Transactions!B$3:B$2000>=DATE(2026,1,1))*(Transactions!B$3:B$2000<=DATE(2026,1,7))*(Transactions!D$3:D$2000)),0) -> 0 | E10: =IFERROR(SUMPRODUCT((Transactions!E$3:E$2000="Coffee")*ISNUMBER(Transactions!B$3:B$2000)*(Transactions!B$3:B$2000>=DATE(2026,1,8))*(Transactions!B$3:B$2000<=DATE(2026,1,15))*(Transactions!D$3:D$2000)),0) -> 0 | F10: =IFERROR(SUMPRODUCT((Transactions!E$3:E$2000="Coffee")*ISNUMBER(Transactions!B$3:B$2000)*(Transactions!B$3:B$2000>=DATE(2026,1,16))*(Transactions!B$3:B$2000<=DATE(2026,1,22))*(Transactions!D$3:D$2000)),0) -> 0 | G10: =IFERROR(SUMPRODUCT((Transactions!E$3:E$2000="Coffee")*ISNUMBER(Transactions!B$3:B$2000)*(Transactions!B$3:B$2000>=DATE(2026,1,23))*(Transactions!B$3:B$2000<=DATE(2026,1,31))*(Transactions!D$3:D$2000)),0) -> 0 | H10: =SUM(D10:G10) -> 0 | I10: =C10-H10 -> 50 | J10: =IFERROR(H10/C10,0) -> 0 | K10: =IF(C10=0,"—",IF(H10=0,"Not started",IF(H10>=C10,"❌ Over budget",IF(H10/C10>=0.8,"⚠️ Near limit","✅ On track")))) -> Not started
B11: Entertainment | C11: 20 | D11: =IFERROR(SUMPRODUCT((Transactions!E$3:E$2000="Entertainment")*ISNUMBER(Transactions!B$3:B$2000)*(Transactions!B$3:B$2000>=DATE(2026,1,1))*(Transactions!B$3:B$2000<=DATE(2026,1,7))*(Transactions!D$3:D$2000)),0) -> 0 | E11: =IFERROR(SUMPRODUCT((Transactions!E$3:E$2000="Entertainment")*ISNUMBER(Transactions!B$3:B$2000)*(Transactions!B$3:B$2000>=DATE(2026,1,8))*(Transactions!B$3:B$2000<=DATE(2026,1,15))*(Transactions!D$3:D$2000)),0) -> 0 | F11: =IFERROR(SUMPRODUCT((Transactions!E$3:E$2000="Entertainment")*ISNUMBER(Transactions!B$3:B$2000)*(Transactions!B$3:B$2000>=DATE(2026,1,16))*(Transactions!B$3:B$2000<=DATE(2026,1,22))*(Transactions!D$3:D$2000)),0) -> 0 | G11: =IFERROR(SUMPRODUCT((Transactions!E$3:E$2000="Entertainment")*ISNUMBER(Transactions!B$3:B$2000)*(Transactions!B$3:B$2000>=DATE(2026,1,23))*(Transactions!B$3:B$2000<=DATE(2026,1,31))*(Transactions!D$3:D$2000)),0) -> 0 | H11: =SUM(D11:G11) -> 0 | I11: =C11-H11 -> 20 | J11: =IFERROR(H11/C11,0) -> 0 | K11: =IF(C11=0,"—",IF(H11=0,"Not started",IF(H11>=C11,"❌ Over budget",IF(H11/C11>=0.8,"⚠️ Near limit","✅ On track")))) -> Not started
B12: Personal Care | C12: 15 | D12: =IFERROR(SUMPRODUCT((Transactions!E$3:E$2000="Personal Care")*ISNUMBER(Transactions!B$3:B$2000)*(Transactions!B$3:B$2000>=DATE(2026,1,1))*(Transactions!B$3:B$2000<=DATE(2026,1,7))*(Transactions!D$3:D$2000)),0) -> 0 | E12: =IFERROR(SUMPRODUCT((Transactions!E$3:E$2000="Personal Care")*ISNUMBER(Transactions!B$3:B$2000)*(Transactions!B$3:B$2000>=DATE(2026,1,8))*(Transactions!B$3:B$2000<=DATE(2026,1,15))*(Transactions!D$3:D$2000)),0) -> 0 | F12: =IFERROR(SUMPRODUCT((Transactions!E$3:E$2000="Personal Care")*ISNUMBER(Transactions!B$3:B$2000)*(Transactions!B$3:B$2000>=DATE(2026,1,16))*(Transactions!B$3:B$2000<=DATE(2026,1,22))*(Transactions!D$3:D$2000)),0) -> 0 | G12: =IFERROR(SUMPRODUCT((Transactions!E$3:E$2000="Personal Care")*ISNUMBER(Transactions!B$3:B$2000)*(Transactions!B$3:B$2000>=DATE(2026,1,23))*(Transactions!B$3:B$2000<=DATE(2026,1,31))*(Transactions!D$3:D$2000)),0) -> 0 | H12: =SUM(D12:G12) -> 0 | I12: =C12-H12 -> 15 | J12: =IFERROR(H12/C12,0) -> 0 | K12: =IF(C12=0,"—",IF(H12=0,"Not started",IF(H12>=C12,"❌ Over budget",IF(H12/C12>=0.8,"⚠️ Near limit","✅ On track")))) -> Not started
B13: Miscellaneous | C13: 40 | D13: =IFERROR(SUMPRODUCT((Transactions!E$3:E$2000="Miscellaneous")*ISNUMBER(Transactions!B$3:B$2000)*(Transactions!B$3:B$2000>=DATE(2026,1,1))*(Transactions!B$3:B$2000<=DATE(2026,1,7))*(Transactions!D$3:D$2000)),0) -> 0 | E13: =IFERROR(SUMPRODUCT((Transactions!E$3:E$2000="Miscellaneous")*ISNUMBER(Transactions!B$3:B$2000)*(Transactions!B$3:B$2000>=DATE(2026,1,8))*(Transactions!B$3:B$2000<=DATE(2026,1,15))*(Transactions!D$3:D$2000)),0) -> 0 | F13: =IFERROR(SUMPRODUCT((Transactions!E$3:E$2000="Miscellaneous")*ISNUMBER(Transactions!B$3:B$2000)*(Transactions!B$3:B$2000>=DATE(2026,1,16))*(Transactions!B$3:B$2000<=DATE(2026,1,22))*(Transactions!D$3:D$2000)),0) -> 0 | G13: =IFERROR(SUMPRODUCT((Transactions!E$3:E$2000="Miscellaneous")*ISNUMBER(Transactions!B$3:B$2000)*(Transactions!B$3:B$2000>=DATE(2026,1,23))*(Transactions!B$3:B$2000<=DATE(2026,1,31))*(Transactions!D$3:D$2000)),0) -> 0 | H13: =SUM(D13:G13) -> 0 | I13: =C13-H13 -> 40 | J13: =IFERROR(H13/C13,0) -> 0 | K13: =IF(C13=0,"—",IF(H13=0,"Not started",IF(H13>=C13,"❌ Over budget",IF(H13/C13>=0.8,"⚠️ Near limit","✅ On track")))) -> Not started
B14: Subscriptions | C14: 10 | D14: =IFERROR(SUMPRODUCT((Transactions!E$3:E$2000="Subscriptions")*ISNUMBER(Transactions!B$3:B$2000)*(Transactions!B$3:B$2000>=DATE(2026,1,1))*(Transactions!B$3:B$2000<=DATE(2026,1,7))*(Transactions!D$3:D$2000)),0) -> 0 | E14: =IFERROR(SUMPRODUCT((Transactions!E$3:E$2000="Subscriptions")*ISNUMBER(Transactions!B$3:B$2000)*(Transactions!B$3:B$2000>=DATE(2026,1,8))*(Transactions!B$3:B$2000<=DATE(2026,1,15))*(Transactions!D$3:D$2000)),0) -> 0 | F14: =IFERROR(SUMPRODUCT((Transactions!E$3:E$2000="Subscriptions")*ISNUMBER(Transactions!B$3:B$2000)*(Transactions!B$3:B$2000>=DATE(2026,1,16))*(Transactions!B$3:B$2000<=DATE(2026,1,22))*(Transactions!D$3:D$2000)),0) -> 0 | G14: =IFERROR(SUMPRODUCT((Transactions!E$3:E$2000="Subscriptions")*ISNUMBER(Transactions!B$3:B$2000)*(Transactions!B$3:B$2000>=DATE(2026,1,23))*(Transactions!B$3:B$2000<=DATE(2026,1,31))*(Transactions!D$3:D$2000)),0) -> 0 | H14: =SUM(D14:G14) -> 0 | I14: =C14-H14 -> 10 | J14: =IFERROR(H14/C14,0) -> 0 | K14: =IF(C14=0,"—",IF(H14=0,"Not started",IF(H14>=C14,"❌ Over budget",IF(H14/C14>=0.8,"⚠️ Near limit","✅ On track")))) -> Not started
B15: Savings | C15: 100 | D15: =IFERROR(SUMPRODUCT((Transactions!E$3:E$2000="Savings")*ISNUMBER(Transactions!B$3:B$2000)*(Transactions!B$3:B$2000>=DATE(2026,1,1))*(Transactions!B$3:B$2000<=DATE(2026,1,7))*(Transactions!D$3:D$2000)),0) -> 0 | E15: =IFERROR(SUMPRODUCT((Transactions!E$3:E$2000="Savings")*ISNUMBER(Transactions!B$3:B$2000)*(Transactions!B$3:B$2000>=DATE(2026,1,8))*(Transactions!B$3:B$2000<=DATE(2026,1,15))*(Transactions!D$3:D$2000)),0) -> 0 | F15: =IFERROR(SUMPRODUCT((Transactions!E$3:E$2000="Savings")*ISNUMBER(Transactions!B$3:B$2000)*(Transactions!B$3:B$2000>=DATE(2026,1,16))*(Transactions!B$3:B$2000<=DATE(2026,1,22))*(Transactions!D$3:D$2000)),0) -> 0 | G15: =IFERROR(SUMPRODUCT((Transactions!E$3:E$2000="Savings")*ISNUMBER(Transactions!B$3:B$2000)*(Transactions!B$3:B$2000>=DATE(2026,1,23))*(Transactions!B$3:B$2000<=DATE(2026,1,31))*(Transactions!D$3:D$2000)),0) -> 0 | H15: =SUM(D15:G15) -> 0 | I15: =C15-H15 -> 100 | J15: =IFERROR(H15/C15,0) -> 0 | K15: =IF(C15=0,"—",IF(H15=0,"Not started",IF(H15>=C15,"❌ Over budget",IF(H15/C15>=0.8,"⚠️ Near limit","✅ On track")))) -> Not started
B16: Other | C16: 0 | D16: =IFERROR(SUMPRODUCT((Transactions!E$3:E$2000="Other")*ISNUMBER(Transactions!B$3:B$2000)*(Transactions!B$3:B$2000>=DATE(2026,1,1))*(Transactions!B$3:B$2000<=DATE(2026,1,7))*(Transactions!D$3:D$2000)),0) -> 0 | E16: =IFERROR(SUMPRODUCT((Transactions!E$3:E$2000="Other")*ISNUMBER(Transactions!B$3:B$2000)*(Transactions!B$3:B$2000>=DATE(2026,1,8))*(Transactions!B$3:B$2000<=DATE(2026,1,15))*(Transactions!D$3:D$2000)),0) -> 0 | F16: =IFERROR(SUMPRODUCT((Transactions!E$3:E$2000="Other")*ISNUMBER(Transactions!B$3:B$2000)*(Transactions!B$3:B$2000>=DATE(2026,1,16))*(Transactions!B$3:B$2000<=DATE(2026,1,22))*(Transactions!D$3:D$2000)),0) -> 0 | G16: =IFERROR(SUMPRODUCT((Transactions!E$3:E$2000="Other")*ISNUMBER(Transactions!B$3:B$2000)*(Transactions!B$3:B$2000>=DATE(2026,1,23))*(Transactions!B$3:B$2000<=DATE(2026,1,31))*(Transactions!D$3:D$2000)),0) -> 0 | H16: =SUM(D16:G16) -> 0 | I16: =C16-H16 -> 0 | J16: =IFERROR(H16/C16,0) -> 0 | K16: =IF(C16=0,"—",IF(H16=0,"Not started",IF(H16>=C16,"❌ Over budget",IF(H16/C16>=0.8,"⚠️ Near limit","✅ On track")))) -> —
B17: TOTAL | C17: =SUM(C7:C16) -> 460 | D17: =SUM(D7:D16) -> 0 | E17: =SUM(E7:E16) -> 0 | F17: =SUM(F7:F16) -> 0 | G17: =SUM(G7:G16) -> 0 | H17: =SUM(H7:H16) -> 0 | I17: =SUM(I7:I16) -> 460 | J17: =IFERROR(H17/C17,0) -> 0
B20: 📅 Weekly Totals Summary
B21: Week | C21: Date Range | D21: Total Spent | E21: Weekly Budget | F21: Over / Under | G21: Status
B22: Week 1 | C22: Jan 1 – Jan 7 | D22: =SUM(D7:D16) -> 0 | E22: =C17/4 -> 115 | F22: =E22-D22 -> 115 | G22: =IF(D22=0,"—",IF(D22>E22,"❌ Over","✅ Under")) -> —
B23: Week 2 | C23: Jan 8 – Jan 15 | D23: =SUM(E7:E16) -> 0 | E23: =C17/4 -> 115 | F23: =E23-D23 -> 115 | G23: =IF(D23=0,"—",IF(D23>E23,"❌ Over","✅ Under")) -> —
B24: Week 3 | C24: Jan 16 – Jan 22 | D24: =SUM(F7:F16) -> 0 | E24: =C17/4 -> 115 | F24: =E24-D24 -> 115 | G24: =IF(D24=0,"—",IF(D24>E24,"❌ Over","✅ Under")) -> —
B25: Week 4 | C25: Jan 23 – Jan 31 | D25: =SUM(G7:G16) -> 0 | E25: =C17/4 -> 115 | F25: =E25-D25 -> 115 | G25: =IF(D25=0,"—",IF(D25>E25,"❌ Over","✅ Under")) -> —

Sheet Budget_Feb
B1: 💰 Weekly Spending Tracker — February 2026
B3: Net Salary | C3: Fixed Outflows | D3: Savings Goal | E3: Spendable
B4: =Setup!C2 -> 883 | C4: =Setup!C11 -> 135.1 | D4: =Setup!C13 -> 0 | E4: =Setup!C14 -> 467.9
B6: Category | C6: Monthly Budget | D6: Week 1 Feb 1–Feb 7 | E6: Week 2 Feb 8–Feb 15 | F6: Week 3 Feb 16–Feb 22 | G6: Week 4 Feb 23–Feb 28 | H6: Total Spent | I6: Remaining | J6: % Used | K6: Status
B7: Groceries | C7: 50 | D7: =IFERROR(SUMPRODUCT((Transactions!E$3:E$2000="Groceries")*ISNUMBER(Transactions!B$3:B$2000)*(Transactions!B$3:B$2000>=DATE(2026,2,1))*(Transactions!B$3:B$2000<=DATE(2026,2,7))*(Transactions!D$3:D$2000)),0) -> 0 | E7: =IFERROR(SUMPRODUCT((Transactions!E$3:E$2000="Groceries")*ISNUMBER(Transactions!B$3:B$2000)*(Transactions!B$3:B$2000>=DATE(2026,2,8))*(Transactions!B$3:B$2000<=DATE(2026,2,15))*(Transactions!D$3:D$2000)),0) -> 0 | F7: =IFERROR(SUMPRODUCT((Transactions!E$3:E$2000="Groceries")*ISNUMBER(Transactions!B$3:B$2000)*(Transactions!B$3:B$2000>=DATE(2026,2,16))*(Transactions!B$3:B$2000<=DATE(2026,2,22))*(Transactions!D$3:D$2000)),0) -> 0 | G7: =IFERROR(SUMPRODUCT((Transactions!E$3:E$2000="Groceries")*ISNUMBER(Transactions!B$3:B$2000)*(Transactions!B$3:B$2000>=DATE(2026,2,23))*(Transactions!B$3:B$2000<=DATE(2026,2,28))*(Transactions!D$3:D$2000)),0) -> 0 | H7: =SUM(D7:G7) -> 0 | I7: =C7-H7 -> 50 | J7: =IFERROR(H7/C7,0) -> 0 | K7: =IF(C7=0,"—",IF(H7=0,"Not started",IF(H7>=C7,"❌ Over budget",IF(H7/C7>=0.8,"⚠️ Near limit","✅ On track")))) -> Not started
B8: Dining Out | C8: 100 | D8: =IFERROR(SUMPRODUCT((Transactions!E$3:E$2000="Dining Out")*ISNUMBER(Transactions!B$3:B$2000)*(Transactions!B$3:B$2000>=DATE(2026,2,1))*(Transactions!B$3:B$2000<=DATE(2026,2,7))*(Transactions!D$3:D$2000)),0) -> 0 | E8: =IFERROR(SUMPRODUCT((Transactions!E$3:E$2000="Dining Out")*ISNUMBER(Transactions!B$3:B$2000)*(Transactions!B$3:B$2000>=DATE(2026,2,8))*(Transactions!B$3:B$2000<=DATE(2026,2,15))*(Transactions!D$3:D$2000)),0) -> 0 | F8: =IFERROR(SUMPRODUCT((Transactions!E$3:E$2000="Dining Out")*ISNUMBER(Transactions!B$3:B$2000)*(Transactions!B$3:B$2000>=DATE(2026,2,16))*(Transactions!B$3:B$2000<=DATE(2026,2,22))*(Transactions!D$3:D$2000)),0) -> 0 | G8: =IFERROR(SUMPRODUCT((Transactions!E$3:E$2000="Dining Out")*ISNUMBER(Transactions!B$3:B$2000)*(Transactions!B$3:B$2000>=DATE(2026,2,23))*(Transactions!B$3:B$2000<=DATE(2026,2,28))*(Transactions!D$3:D$2000)),0) -> 0 | H8: =SUM(D8:G8) -> 0 | I8: =C8-H8 -> 100 | J8: =IFERROR(H8/C8,0) -> 0 | K8: =IF(C8=0,"—",IF(H8=0,"Not started",IF(H8>=C8,"❌ Over budget",IF(H8/C8>=0.8,"⚠️ Near limit","✅ On track")))) -> Not started
B9: Fuel | C9: 75 | D9: =IFERROR(SUMPRODUCT((Transactions!E$3:E$2000="Fuel")*ISNUMBER(Transactions!B$3:B$2000)*(Transactions!B$3:B$2000>=DATE(2026,2,1))*(Transactions!B$3:B$2000<=DATE(2026,2,7))*(Transactions!D$3:D$2000)),0) -> 0 | E9: =IFERROR(SUMPRODUCT((Transactions!E$3:E$2000="Fuel")*ISNUMBER(Transactions!B$3:B$2000)*(Transactions!B$3:B$2000>=DATE(2026,2,8))*(Transactions!B$3:B$2000<=DATE(2026,2,15))*(Transactions!D$3:D$2000)),0) -> 0 | F9: =IFERROR(SUMPRODUCT((Transactions!E$3:E$2000="Fuel")*ISNUMBER(Transactions!B$3:B$2000)*(Transactions!B$3:B$2000>=DATE(2026,2,16))*(Transactions!B$3:B$2000<=DATE(2026,2,22))*(Transactions!D$3:D$2000)),0) -> 0 | G9: =IFERROR(SUMPRODUCT((Transactions!E$3:E$2000="Fuel")*ISNUMBER(Transactions!B$3:B$2000)*(Transactions!B$3:B$2000>=DATE(2026,2,23))*(Transactions!B$3:B$2000<=DATE(2026,2,28))*(Transactions!D$3:D$2000)),0) -> 0 | H9: =SUM(D9:G9) -> 0 | I9: =C9-H9 -> 75 | J9: =IFERROR(H9/C9,0) -> 0 | K9: =IF(C9=0,"—",IF(H9=0,"Not started",IF(H9>=C9,"❌ Over budget",IF(H9/C9>=0.8,"⚠️ Near limit","✅ On track")))) -> Not started
B10: Coffee | C10: 50 | D10: =IFERROR(SUMPRODUCT((Transactions!E$3:E$2000="Coffee")*ISNUMBER(Transactions!B$3:B$2000)*(Transactions!B$3:B$2000>=DATE(2026,2,1))*(Transactions!B$3:B$2000<=DATE(2026,2,7))*(Transactions!D$3:D$2000)),0) -> 0 | E10: =IFERROR(SUMPRODUCT((Transactions!E$3:E$2000="Coffee")*ISNUMBER(Transactions!B$3:B$2000)*(Transactions!B$3:B$2000>=DATE(2026,2,8))*(Transactions!B$3:B$2000<=DATE(2026,2,15))*(Transactions!D$3:D$2000)),0) -> 0 | F10: =IFERROR(SUMPRODUCT((Transactions!E$3:E$2000="Coffee")*ISNUMBER(Transactions!B$3:B$2000)*(Transactions!B$3:B$2000>=DATE(2026,2,16))*(Transactions!B$3:B$2000<=DATE(2026,2,22))*(Transactions!D$3:D$2000)),0) -> 0 | G10: =IFERROR(SUMPRODUCT((Transactions!E$3:E$2000="Coffee")*ISNUMBER(Transactions!B$3:B$2000)*(Transactions!B$3:B$2000>=DATE(2026,2,23))*(Transactions!B$3:B$2000<=DATE(2026,2,28))*(Transactions!D$3:D$2000)),0) -> 0 | H10: =SUM(D10:G10) -> 0 | I10: =C10-H10 -> 50 | J10: =IFERROR(H10/C10,0) -> 0 | K10: =IF(C10=0,"—",IF(H10=0,"Not started",IF(H10>=C10,"❌ Over budget",IF(H10/C10>=0.8,"⚠️ Near limit","✅ On track")))) -> Not started
B11: Entertainment | C11: 20 | D11: =IFERROR(SUMPRODUCT((Transactions!E$3:E$2000="Entertainment")*ISNUMBER(Transactions!B$3:B$2000)*(Transactions!B$3:B$2000>=DATE(2026,2,1))*(Transactions!B$3:B$2000<=DATE(2026,2,7))*(Transactions!D$3:D$2000)),0) -> 0 | E11: =IFERROR(SUMPRODUCT((Transactions!E$3:E$2000="Entertainment")*ISNUMBER(Transactions!B$3:B$2000)*(Transactions!B$3:B$2000>=DATE(2026,2,8))*(Transactions!B$3:B$2000<=DATE(2026,2,15))*(Transactions!D$3:D$2000)),0) -> 0 | F11: =IFERROR(SUMPRODUCT((Transactions!E$3:E$2000="Entertainment")*ISNUMBER(Transactions!B$3:B$2000)*(Transactions!B$3:B$2000>=DATE(2026,2,16))*(Transactions!B$3:B$2000<=DATE(2026,2,22))*(Transactions!D$3:D$2000)),0) -> 0 | G11: =IFERROR(SUMPRODUCT((Transactions!E$3:E$2000="Entertainment")*ISNUMBER(Transactions!B$3:B$2000)*(Transactions!B$3:B$2000>=DATE(2026,2,23))*(Transactions!B$3:B$2000<=DATE(2026,2,28))*(Transactions!D$3:D$2000)),0) -> 0 | H11: =SUM(D11:G11) -> 0 | I11: =C11-H11 -> 20 | J11: =IFERROR(H11/C11,0) -> 0 | K11: =IF(C11=0,"—",IF(H11=0,"Not started",IF(H11>=C11,"❌ Over budget",IF(H11/C11>=0.8,"⚠️ Near limit","✅ On track")))) -> Not started
B12: Personal Care | C12: 15 | D12: =IFERROR(SUMPRODUCT((Transactions!E$3:E$2000="Personal Care")*ISNUMBER(Transactions!B$3:B$2000)*(Transactions!B$3:B$2000>=DATE(2026,2,1))*(Transactions!B$3:B$2000<=DATE(2026,2,7))*(Transactions!D$3:D$2000)),0) -> 0 | E12: =IFERROR(SUMPRODUCT((Transactions!E$3:E$2000="Personal Care")*ISNUMBER(Transactions!B$3:B$2000)*(Transactions!B$3:B$2000>=DATE(2026,2,8))*(Transactions!B$3:B$2000<=DATE(2026,2,15))*(Transactions!D$3:D$2000)),0) -> 0 | F12: =IFERROR(SUMPRODUCT((Transactions!E$3:E$2000="Personal Care")*ISNUMBER(Transactions!B$3:B$2000)*(Transactions!B$3:B$2000>=DATE(2026,2,16))*(Transactions!B$3:B$2000<=DATE(2026,2,22))*(Transactions!D$3:D$2000)),0) -> 0 | G12: =IFERROR(SUMPRODUCT((Transactions!E$3:E$2000="Personal Care")*ISNUMBER(Transactions!B$3:B$2000)*(Transactions!B$3:B$2000>=DATE(2026,2,23))*(Transactions!B$3:B$2000<=DATE(2026,2,28))*(Transactions!D$3:D$2000)),0) -> 0 | H12: =SUM(D12:G12) -> 0 | I12: =C12-H12 -> 15 | J12: =IFERROR(H12/C12,0) -> 0 | K12: =IF(C12=0,"—",IF(H12=0,"Not started",IF(H12>=C12,"❌ Over budget",IF(H12/C12>=0.8,"⚠️ Near limit","✅ On track")))) -> Not started
B13: Miscellaneous | C13: 40 | D13: =IFERROR(SUMPRODUCT((Transactions!E$3:E$2000="Miscellaneous")*ISNUMBER(Transactions!B$3:B$2000)*(Transactions!B$3:B$2000>=DATE(2026,2,1))*(Transactions!B$3:B$2000<=DATE(2026,2,7))*(Transactions!D$3:D$2000)),0) -> 0 | E13: =IFERROR(SUMPRODUCT((Transactions!E$3:E$2000="Miscellaneous")*ISNUMBER(Transactions!B$3:B$2000)*(Transactions!B$3:B$2000>=DATE(2026,2,8))*(Transactions!B$3:B$2000<=DATE(2026,2,15))*(Transactions!D$3:D$2000)),0) -> 0 | F13: =IFERROR(SUMPRODUCT((Transactions!E$3:E$2000="Miscellaneous")*ISNUMBER(Transactions!B$3:B$2000)*(Transactions!B$3:B$2000>=DATE(2026,2,16))*(Transactions!B$3:B$2000<=DATE(2026,2,22))*(Transactions!D$3:D$2000)),0) -> 0 | G13: =IFERROR(SUMPRODUCT((Transactions!E$3:E$2000="Miscellaneous")*ISNUMBER(Transactions!B$3:B$2000)*(Transactions!B$3:B$2000>=DATE(2026,2,23))*(Transactions!B$3:B$2000<=DATE(2026,2,28))*(Transactions!D$3:D$2000)),0) -> 0 | H13: =SUM(D13:G13) -> 0 | I13: =C13-H13 -> 40 | J13: =IFERROR(H13/C13,0) -> 0 | K13: =IF(C13=0,"—",IF(H13=0,"Not started",IF(H13>=C13,"❌ Over budget",IF(H13/C13>=0.8,"⚠️ Near limit","✅ On track")))) -> Not started
B14: Subscriptions | C14: 10 | D14: =IFERROR(SUMPRODUCT((Transactions!E$3:E$2000="Subscriptions")*ISNUMBER(Transactions!B$3:B$2000)*(Transactions!B$3:B$2000>=DATE(2026,2,1))*(Transactions!B$3:B$2000<=DATE(2026,2,7))*(Transactions!D$3:D$2000)),0) -> 0 | E14: =IFERROR(SUMPRODUCT((Transactions!E$3:E$2000="Subscriptions")*ISNUMBER(Transactions!B$3:B$2000)*(Transactions!B$3:B$2000>=DATE(2026,2,8))*(Transactions!B$3:B$2000<=DATE(2026,2,15))*(Transactions!D$3:D$2000)),0) -> 0 | F14: =IFERROR(SUMPRODUCT((Transactions!E$3:E$2000="Subscriptions")*ISNUMBER(Transactions!B$3:B$2000)*(Transactions!B$3:B$2000>=DATE(2026,2,16))*(Transactions!B$3:B$2000<=DATE(2026,2,22))*(Transactions!D$3:D$2000)),0) -> 0 | G14: =IFERROR(SUMPRODUCT((Transactions!E$3:E$2000="Subscriptions")*ISNUMBER(Transactions!B$3:B$2000)*(Transactions!B$3:B$2000>=DATE(2026,2,23))*(Transactions!B$3:B$2000<=DATE(2026,2,28))*(Transactions!D$3:D$2000)),0) -> 0 | H14: =SUM(D14:G14) -> 0 | I14: =C14-H14 -> 10 | J14: =IFERROR(H14/C14,0) -> 0 | K14: =IF(C14=0,"—",IF(H14=0,"Not started",IF(H14>=C14,"❌ Over budget",IF(H14/C14>=0.8,"⚠️ Near limit","✅ On track")))) -> Not started
B15: Savings | C15: 100 | D15: =IFERROR(SUMPRODUCT((Transactions!E$3:E$2000="Savings")*ISNUMBER(Transactions!B$3:B$2000)*(Transactions!B$3:B$2000>=DATE(2026,2,1))*(Transactions!B$3:B$2000<=DATE(2026,2,7))*(Transactions!D$3:D$2000)),0) -> 0 | E15: =IFERROR(SUMPRODUCT((Transactions!E$3:E$2000="Savings")*ISNUMBER(Transactions!B$3:B$2000)*(Transactions!B$3:B$2000>=DATE(2026,2,8))*(Transactions!B$3:B$2000<=DATE(2026,2,15))*(Transactions!D$3:D$2000)),0) -> 0 | F15: =IFERROR(SUMPRODUCT((Transactions!E$3:E$2000="Savings")*ISNUMBER(Transactions!B$3:B$2000)*(Transactions!B$3:B$2000>=DATE(2026,2,16))*(Transactions!B$3:B$2000<=DATE(2026,2,22))*(Transactions!D$3:D$2000)),0) -> 0 | G15: =IFERROR(SUMPRODUCT((Transactions!E$3:E$2000="Savings")*ISNUMBER(Transactions!B$3:B$2000)*(Transactions!B$3:B$2000>=DATE(2026,2,23))*(Transactions!B$3:B$2000<=DATE(2026,2,28))*(Transactions!D$3:D$2000)),0) -> 0 | H15: =SUM(D15:G15) -> 0 | I15: =C15-H15 -> 100 | J15: =IFERROR(H15/C15,0) -> 0 | K15: =IF(C15=0,"—",IF(H15=0,"Not started",IF(H15>=C15,"❌ Over budget",IF(H15/C15>=0.8,"⚠️ Near limit","✅ On track")))) -> Not started
B16: Other | C16: 0 | D16: =IFERROR(SUMPRODUCT((Transactions!E$3:E$2000="Other")*ISNUMBER(Transactions!B$3:B$2000)*(Transactions!B$3:B$2000>=DATE(2026,2,1))*(Transactions!B$3:B$2000<=DATE(2026,2,7))*(Transactions!D$3:D$2000)),0) -> 0 | E16: =IFERROR(SUMPRODUCT((Transactions!E$3:E$2000="Other")*ISNUMBER(Transactions!B$3:B$2000)*(Transactions!B$3:B$2000>=DATE(2026,2,8))*(Transactions!B$3:B$2000<=DATE(2026,2,15))*(Transactions!D$3:D$2000)),0) -> 0 | F16: =IFERROR(SUMPRODUCT((Transactions!E$3:E$2000="Other")*ISNUMBER(Transactions!B$3:B$2000)*(Transactions!B$3:B$2000>=DATE(2026,2,16))*(Transactions!B$3:B$2000<=DATE(2026,2,22))*(Transactions!D$3:D$2000)),0) -> 0 | G16: =IFERROR(SUMPRODUCT((Transactions!E$3:E$2000="Other")*ISNUMBER(Transactions!B$3:B$2000)*(Transactions!B$3:B$2000>=DATE(2026,2,23))*(Transactions!B$3:B$2000<=DATE(2026,2,28))*(Transactions!D$3:D$2000)),0) -> 0 | H16: =SUM(D16:G16) -> 0 | I16: =C16-H16 -> 0 | J16: =IFERROR(H16/C16,0) -> 0 | K16: =IF(C16=0,"—",IF(H16=0,"Not started",IF(H16>=C16,"❌ Over budget",IF(H16/C16>=0.8,"⚠️ Near limit","✅ On track")))) -> —
B17: TOTAL | C17: =SUM(C7:C16) -> 460 | D17: =SUM(D7:D16) -> 0 | E17: =SUM(E7:E16) -> 0 | F17: =SUM(F7:F16) -> 0 | G17: =SUM(G7:G16) -> 0 | H17: =SUM(H7:H16) -> 0 | I17: =SUM(I7:I16) -> 460 | J17: =IFERROR(H17/C17,0) -> 0
B20: 📅 Weekly Totals Summary
B21: Week | C21: Date Range | D21: Total Spent | E21: Weekly Budget | F21: Over / Under | G21: Status
B22: Week 1 | C22: Feb 1 – Feb 7 | D22: =SUM(D7:D16) -> 0 | E22: =C17/4 -> 115 | F22: =E22-D22 -> 115 | G22: =IF(D22=0,"—",IF(D22>E22,"❌ Over","✅ Under")) -> —
B23: Week 2 | C23: Feb 8 – Feb 15 | D23: =SUM(E7:E16) -> 0 | E23: =C17/4 -> 115 | F23: =E23-D23 -> 115 | G23: =IF(D23=0,"—",IF(D23>E23,"❌ Over","✅ Under")) -> —
B24: Week 3 | C24: Feb 16 – Feb 22 | D24: =SUM(F7:F16) -> 0 | E24: =C17/4 -> 115 | F24: =E24-D24 -> 115 | G24: =IF(D24=0,"—",IF(D24>E24,"❌ Over","✅ Under")) -> —
B25: Week 4 | C25: Feb 23 – Feb 28 | D25: =SUM(G7:G16) -> 0 | E25: =C17/4 -> 115 | F25: =E25-D25 -> 115 | G25: =IF(D25=0,"—",IF(D25>E25,"❌ Over","✅ Under")) -> —

Sheet Budget_Mar
B1: 💰 Weekly Spending Tracker — March 2026
B3: Net Salary | C3: Fixed Outflows | D3: Savings Goal | E3: Spendable
B4: =Setup!C2 -> 883 | C4: =Setup!C11 -> 135.1 | D4: =Setup!C13 -> 0 | E4: =Setup!C14 -> 467.9
B6: Category | C6: Monthly Budget | D6: Week 1 Mar 1–Mar 7 | E6: Week 2 Mar 8–Mar 15 | F6: Week 3 Mar 16–Mar 22 | G6: Week 4 Mar 23–Mar 31 | H6: Total Spent | I6: Remaining | J6: % Used | K6: Status
B7: Groceries | C7: 50 | D7: =IFERROR(SUMPRODUCT((Transactions!E$3:E$2000="Groceries")*ISNUMBER(Transactions!B$3:B$2000)*(Transactions!B$3:B$2000>=DATE(2026,3,1))*(Transactions!B$3:B$2000<=DATE(2026,3,7))*(Transactions!D$3:D$2000)),0) -> 0 | E7: =IFERROR(SUMPRODUCT((Transactions!E$3:E$2000="Groceries")*ISNUMBER(Transactions!B$3:B$2000)*(Transactions!B$3:B$2000>=DATE(2026,3,8))*(Transactions!B$3:B$2000<=DATE(2026,3,15))*(Transactions!D$3:D$2000)),0) -> 0 | F7: =IFERROR(SUMPRODUCT((Transactions!E$3:E$2000="Groceries")*ISNUMBER(Transactions!B$3:B$2000)*(Transactions!B$3:B$2000>=DATE(2026,3,16))*(Transactions!B$3:B$2000<=DATE(2026,3,22))*(Transactions!D$3:D$2000)),0) -> 0 | G7: =IFERROR(SUMPRODUCT((Transactions!E$3:E$2000="Groceries")*ISNUMBER(Transactions!B$3:B$2000)*(Transactions!B$3:B$2000>=DATE(2026,3,23))*(Transactions!B$3:B$2000<=DATE(2026,3,31))*(Transactions!D$3:D$2000)),0) -> 0 | H7: =SUM(D7:G7) -> 0 | I7: =C7-H7 -> 50 | J7: =IFERROR(H7/C7,0) -> 0 | K7: =IF(C7=0,"—",IF(H7=0,"Not started",IF(H7>=C7,"❌ Over budget",IF(H7/C7>=0.8,"⚠️ Near limit","✅ On track")))) -> Not started
B8: Dining Out | C8: 100 | D8: =IFERROR(SUMPRODUCT((Transactions!E$3:E$2000="Dining Out")*ISNUMBER(Transactions!B$3:B$2000)*(Transactions!B$3:B$2000>=DATE(2026,3,1))*(Transactions!B$3:B$2000<=DATE(2026,3,7))*(Transactions!D$3:D$2000)),0) -> 0 | E8: =IFERROR(SUMPRODUCT((Transactions!E$3:E$2000="Dining Out")*ISNUMBER(Transactions!B$3:B$2000)*(Transactions!B$3:B$2000>=DATE(2026,3,8))*(Transactions!B$3:B$2000<=DATE(2026,3,15))*(Transactions!D$3:D$2000)),0) -> 0 | F8: =IFERROR(SUMPRODUCT((Transactions!E$3:E$2000="Dining Out")*ISNUMBER(Transactions!B$3:B$2000)*(Transactions!B$3:B$2000>=DATE(2026,3,16))*(Transactions!B$3:B$2000<=DATE(2026,3,22))*(Transactions!D$3:D$2000)),0) -> 0 | G8: =IFERROR(SUMPRODUCT((Transactions!E$3:E$2000="Dining Out")*ISNUMBER(Transactions!B$3:B$2000)*(Transactions!B$3:B$2000>=DATE(2026,3,23))*(Transactions!B$3:B$2000<=DATE(2026,3,31))*(Transactions!D$3:D$2000)),0) -> 0 | H8: =SUM(D8:G8) -> 0 | I8: =C8-H8 -> 100 | J8: =IFERROR(H8/C8,0) -> 0 | K8: =IF(C8=0,"—",IF(H8=0,"Not started",IF(H8>=C8,"❌ Over budget",IF(H8/C8>=0.8,"⚠️ Near limit","✅ On track")))) -> Not started
B9: Fuel | C9: 75 | D9: =IFERROR(SUMPRODUCT((Transactions!E$3:E$2000="Fuel")*ISNUMBER(Transactions!B$3:B$2000)*(Transactions!B$3:B$2000>=DATE(2026,3,1))*(Transactions!B$3:B$2000<=DATE(2026,3,7))*(Transactions!D$3:D$2000)),0) -> 0 | E9: =IFERROR(SUMPRODUCT((Transactions!E$3:E$2000="Fuel")*ISNUMBER(Transactions!B$3:B$2000)*(Transactions!B$3:B$2000>=DATE(2026,3,8))*(Transactions!B$3:B$2000<=DATE(2026,3,15))*(Transactions!D$3:D$2000)),0) -> 0 | F9: =IFERROR(SUMPRODUCT((Transactions!E$3:E$2000="Fuel")*ISNUMBER(Transactions!B$3:B$2000)*(Transactions!B$3:B$2000>=DATE(2026,3,16))*(Transactions!B$3:B$2000<=DATE(2026,3,22))*(Transactions!D$3:D$2000)),0) -> 0 | G9: =IFERROR(SUMPRODUCT((Transactions!E$3:E$2000="Fuel")*ISNUMBER(Transactions!B$3:B$2000)*(Transactions!B$3:B$2000>=DATE(2026,3,23))*(Transactions!B$3:B$2000<=DATE(2026,3,31))*(Transactions!D$3:D$2000)),0) -> 0 | H9: =SUM(D9:G9) -> 0 | I9: =C9-H9 -> 75 | J9: =IFERROR(H9/C9,0) -> 0 | K9: =IF(C9=0,"—",IF(H9=0,"Not started",IF(H9>=C9,"❌ Over budget",IF(H9/C9>=0.8,"⚠️ Near limit","✅ On track")))) -> Not started
B10: Coffee | C10: 50 | D10: =IFERROR(SUMPRODUCT((Transactions!E$3:E$2000="Coffee")*ISNUMBER(Transactions!B$3:B$2000)*(Transactions!B$3:B$2000>=DATE(2026,3,1))*(Transactions!B$3:B$2000<=DATE(2026,3,7))*(Transactions!D$3:D$2000)),0) -> 0 | E10: =IFERROR(SUMPRODUCT((Transactions!E$3:E$2000="Coffee")*ISNUMBER(Transactions!B$3:B$2000)*(Transactions!B$3:B$2000>=DATE(2026,3,8))*(Transactions!B$3:B$2000<=DATE(2026,3,15))*(Transactions!D$3:D$2000)),0) -> 0 | F10: =IFERROR(SUMPRODUCT((Transactions!E$3:E$2000="Coffee")*ISNUMBER(Transactions!B$3:B$2000)*(Transactions!B$3:B$2000>=DATE(2026,3,16))*(Transactions!B$3:B$2000<=DATE(2026,3,22))*(Transactions!D$3:D$2000)),0) -> 0 | G10: =IFERROR(SUMPRODUCT((Transactions!E$3:E$2000="Coffee")*ISNUMBER(Transactions!B$3:B$2000)*(Transactions!B$3:B$2000>=DATE(2026,3,23))*(Transactions!B$3:B$2000<=DATE(2026,3,31))*(Transactions!D$3:D$2000)),0) -> 0 | H10: =SUM(D10:G10) -> 0 | I10: =C10-H10 -> 50 | J10: =IFERROR(H10/C10,0) -> 0 | K10: =IF(C10=0,"—",IF(H10=0,"Not started",IF(H10>=C10,"❌ Over budget",IF(H10/C10>=0.8,"⚠️ Near limit","✅ On track")))) -> Not started
B11: Entertainment | C11: 20 | D11: =IFERROR(SUMPRODUCT((Transactions!E$3:E$2000="Entertainment")*ISNUMBER(Transactions!B$3:B$2000)*(Transactions!B$3:B$2000>=DATE(2026,3,1))*(Transactions!B$3:B$2000<=DATE(2026,3,7))*(Transactions!D$3:D$2000)),0) -> 0 | E11: =IFERROR(SUMPRODUCT((Transactions!E$3:E$2000="Entertainment")*ISNUMBER(Transactions!B$3:B$2000)*(Transactions!B$3:B$2000>=DATE(2026,3,8))*(Transactions!B$3:B$2000<=DATE(2026,3,15))*(Transactions!D$3:D$2000)),0) -> 0 | F11: =IFERROR(SUMPRODUCT((Transactions!E$3:E$2000="Entertainment")*ISNUMBER(Transactions!B$3:B$2000)*(Transactions!B$3:B$2000>=DATE(2026,3,16))*(Transactions!B$3:B$2000<=DATE(2026,3,22))*(Transactions!D$3:D$2000)),0) -> 0 | G11: =IFERROR(SUMPRODUCT((Transactions!E$3:E$2000="Entertainment")*ISNUMBER(Transactions!B$3:B$2000)*(Transactions!B$3:B$2000>=DATE(2026,3,23))*(Transactions!B$3:B$2000<=DATE(2026,3,31))*(Transactions!D$3:D$2000)),0) -> 0 | H11: =SUM(D11:G11) -> 0 | I11: =C11-H11 -> 20 | J11: =IFERROR(H11/C11,0) -> 0 | K11: =IF(C11=0,"—",IF(H11=0,"Not started",IF(H11>=C11,"❌ Over budget",IF(H11/C11>=0.8,"⚠️ Near limit","✅ On track")))) -> Not started
B12: Personal Care | C12: 15 | D12: =IFERROR(SUMPRODUCT((Transactions!E$3:E$2000="Personal Care")*ISNUMBER(Transactions!B$3:B$2000)*(Transactions!B$3:B$2000>=DATE(2026,3,1))*(Transactions!B$3:B$2000<=DATE(2026,3,7))*(Transactions!D$3:D$2000)),0) -> 0 | E12: =IFERROR(SUMPRODUCT((Transactions!E$3:E$2000="Personal Care")*ISNUMBER(Transactions!B$3:B$2000)*(Transactions!B$3:B$2000>=DATE(2026,3,8))*(Transactions!B$3:B$2000<=DATE(2026,3,15))*(Transactions!D$3:D$2000)),0) -> 0 | F12: =IFERROR(SUMPRODUCT((Transactions!E$3:E$2000="Personal Care")*ISNUMBER(Transactions!B$3:B$2000)*(Transactions!B$3:B$2000>=DATE(2026,3,16))*(Transactions!B$3:B$2000<=DATE(2026,3,22))*(Transactions!D$3:D$2000)),0) -> 0 | G12: =IFERROR(SUMPRODUCT((Transactions!E$3:E$2000="Personal Care")*ISNUMBER(Transactions!B$3:B$2000)*(Transactions!B$3:B$2000>=DATE(2026,3,23))*(Transactions!B$3:B$2000<=DATE(2026,3,31))*(Transactions!D$3:D$2000)),0) -> 0 | H12: =SUM(D12:G12) -> 0 | I12: =C12-H12 -> 15 | J12: =IFERROR(H12/C12,0) -> 0 | K12: =IF(C12=0,"—",IF(H12=0,"Not started",IF(H12>=C12,"❌ Over budget",IF(H12/C12>=0.8,"⚠️ Near limit","✅ On track")))) -> Not started
B13: Miscellaneous | C13: 40 | D13: =IFERROR(SUMPRODUCT((Transactions!E$3:E$2000="Miscellaneous")*ISNUMBER(Transactions!B$3:B$2000)*(Transactions!B$3:B$2000>=DATE(2026,3,1))*(Transactions!B$3:B$2000<=DATE(2026,3,7))*(Transactions!D$3:D$2000)),0) -> 0 | E13: =IFERROR(SUMPRODUCT((Transactions!E$3:E$2000="Miscellaneous")*ISNUMBER(Transactions!B$3:B$2000)*(Transactions!B$3:B$2000>=DATE(2026,3,8))*(Transactions!B$3:B$2000<=DATE(2026,3,15))*(Transactions!D$3:D$2000)),0) -> 0 | F13: =IFERROR(SUMPRODUCT((Transactions!E$3:E$2000="Miscellaneous")*ISNUMBER(Transactions!B$3:B$2000)*(Transactions!B$3:B$2000>=DATE(2026,3,16))*(Transactions!B$3:B$2000<=DATE(2026,3,22))*(Transactions!D$3:D$2000)),0) -> 0 | G13: =IFERROR(SUMPRODUCT((Transactions!E$3:E$2000="Miscellaneous")*ISNUMBER(Transactions!B$3:B$2000)*(Transactions!B$3:B$2000>=DATE(2026,3,23))*(Transactions!B$3:B$2000<=DATE(2026,3,31))*(Transactions!D$3:D$2000)),0) -> 0 | H13: =SUM(D13:G13) -> 0 | I13: =C13-H13 -> 40 | J13: =IFERROR(H13/C13,0) -> 0 | K13: =IF(C13=0,"—",IF(H13=0,"Not started",IF(H13>=C13,"❌ Over budget",IF(H13/C13>=0.8,"⚠️ Near limit","✅ On track")))) -> Not started
B14: Subscriptions | C14: 10 | D14: =IFERROR(SUMPRODUCT((Transactions!E$3:E$2000="Subscriptions")*ISNUMBER(Transactions!B$3:B$2000)*(Transactions!B$3:B$2000>=DATE(2026,3,1))*(Transactions!B$3:B$2000<=DATE(2026,3,7))*(Transactions!D$3:D$2000)),0) -> 0 | E14: =IFERROR(SUMPRODUCT((Transactions!E$3:E$2000="Subscriptions")*ISNUMBER(Transactions!B$3:B$2000)*(Transactions!B$3:B$2000>=DATE(2026,3,8))*(Transactions!B$3:B$2000<=DATE(2026,3,15))*(Transactions!D$3:D$2000)),0) -> 0 | F14: =IFERROR(SUMPRODUCT((Transactions!E$3:E$2000="Subscriptions")*ISNUMBER(Transactions!B$3:B$2000)*(Transactions!B$3:B$2000>=DATE(2026,3,16))*(Transactions!B$3:B$2000<=DATE(2026,3,22))*(Transactions!D$3:D$2000)),0) -> 0 | G14: =IFERROR(SUMPRODUCT((Transactions!E$3:E$2000="Subscriptions")*ISNUMBER(Transactions!B$3:B$2000)*(Transactions!B$3:B$2000>=DATE(2026,3,23))*(Transactions!B$3:B$2000<=DATE(2026,3,31))*(Transactions!D$3:D$2000)),0) -> 0 | H14: =SUM(D14:G14) -> 0 | I14: =C14-H14 -> 10 | J14: =IFERROR(H14/C14,0) -> 0 | K14: =IF(C14=0,"—",IF(H14=0,"Not started",IF(H14>=C14,"❌ Over budget",IF(H14/C14>=0.8,"⚠️ Near limit","✅ On track")))) -> Not started
